<?xml version='1.0'?>

<robot name="myrobot" xmlns:xacro="http://www.ros.org/wiki/xacro">

  <xacro:include filename="$(find mybot_description)/urdf/mybot.gazebo" />
  <xacro:include filename="$(find mybot_description)/urdf/materials.xacro" />
  <xacro:include filename="$(find mybot_description)/urdf/macros.xacro" />


  <link name='chassis'>
    <pose>0 0 0 0 0 0</pose>

    <inertial>
      <mass value="3"/>
      <origin xyz="0 0 0" rpy=" 0 0 0"/>
	  <box_inertia m="3" x="0.3" y="0.23" z="0.07"/>
    </inertial>

    <collision name='collision'>
      <geometry>
        <box size=".28 .23 .07"/>
      </geometry>
    </collision>

    <visual name='chassis_visual'>
      <origin xyz="0 0 0" rpy=" 0 0 0"/>
      <geometry>
        <box size=".28 .23 .07"/>
      </geometry>
    </visual>

    <collision name='collision'>
      <geometry>
        <box size=".03 .23 .044"/>
      </geometry>
    </collision>

    <visual name='chassis_visual'>
      <origin xyz="0.155 0 -0.013" rpy=" 0 0 0"/>
      <geometry>
        <box size=".03 .23 .044"/>
      </geometry>
    </visual>

    <collision name='collision'>
      <geometry>
        <box size=".04 .23 .04"/>
      </geometry>
    </collision>

    <visual name='chassis_visual'>
      <origin xyz="0.1415 0 .007" rpy="0 0.754 0"/>
      <geometry>
        <box size=".04 .23 .04"/>
      </geometry>
    </visual>

    <collision name='caster_collision1'>
      <origin xyz="-0.1075 0.07 -0.035" rpy=" 0 0 0"/>
      <geometry>
        <sphere radius="0.0325"/>
      </geometry>
      <surface>
        <friction>
          <ode>
            <mu>0</mu>
            <mu2>0</mu2>
            <slip1>1.0</slip1>
            <slip2>1.0</slip2>
          </ode>
        </friction>
      </surface>
    </collision>

    <visual name='caster_visua1'>
      <origin xyz="-0.1075 0.07 -0.035" rpy=" 0 0 0"/>
      <geometry>
        <sphere radius="0.0325"/>
      </geometry>
      <inertial>
		  <mass value="1"/>
      </inertial>
    </visual>
    
    
    <collision name='caster_collision2'>
      <origin xyz="-0.1075 -0.07 -0.035" rpy=" 0 0 0"/>
      <geometry>
        <sphere radius="0.0325"/>
      </geometry>
      <surface>
        <friction>
          <ode>
            <mu>0</mu>
            <mu2>0</mu2>
            <slip1>1.0</slip1>
            <slip2>1.0</slip2>
          </ode>
        </friction>
      </surface>
    </collision>

    <visual name='caster_visua2'>
      <origin xyz="-0.1075 -0.07 -0.035" rpy=" 0 0 0"/>
      <geometry>
        <sphere radius="0.0325"/>
      </geometry>
      <inertial>
		  <mass value="1"/>
      </inertial>
    </visual>
  </link>
  
  
<link name="imu_link">
  <inertial>
    <mass value="0.001"/>
    <origin rpy="0 0 0" xyz="0 0 0"/>
    <inertia ixx="0.0001" ixy="0" ixz="0" iyy="0.000001" iyz="0" izz="0.0001"/>
  </inertial>
  <visual>
    <origin rpy="0 0 0" xyz="0 0 0"/>
    <geometry>
      <box size="0.001 0.001 0.001"/>
    </geometry>
  </visual>
  <collision>
    <origin rpy="0 0 0" xyz="0 0 0"/>
    <geometry>
      <box size=".001 .001 .001"/>
    </geometry>
  </collision>
</link>


  <link name="left_wheel">
    <!--origin xyz="0.1 0.13 0.1" rpy="0 1.5707 1.5707"/-->
    <collision name="collision">
      <origin xyz="0 0 0" rpy="0 1.5707 1.5707"/>
      <geometry>
        <cylinder radius=".0325" length=".02"/>
      </geometry>
    </collision>
    <visual name="left_wheel_visual">
      <origin xyz="0 0 0" rpy="0 1.5707 1.5707"/>
      <geometry>
        <cylinder radius=".0325" length=".02"/>
      </geometry>
    </visual>
    <inertial>
      <origin xyz="0 0 0" rpy="0 1.5707 1.5707"/>
      <mass value="1"/>
      <cylinder_inertia m="1" r="0.0325" h="0.02"/>
    </inertial>
  </link>

  <link name="right_wheel">
    <!--origin xyz="0.1 -0.13 0.1" rpy="0 1.5707 1.5707"/-->
    <collision name="collision">
      <origin xyz="0 0 0" rpy="0 1.5707 1.5707"/>
      <geometry>
        <cylinder radius=".0325" length=".02"/>
      </geometry>
    </collision>
    <visual name="right_wheel_visual">
      <origin xyz="0 0 0" rpy="0 1.5707 1.5707"/>
      <geometry>
        <cylinder radius=".0325" length=".02"/>
      </geometry>
    </visual>
    <inertial>
      <origin xyz="0 0 0" rpy="0 1.5707 1.5707"/>
      <mass value="1"/>
      <cylinder_inertia m="1" r="0.0325" h="0.02"/>
    </inertial>
  </link>
  
  
  <joint name="imu_joint" type="fixed">
    <axis xyz="1 0 0"/> <!-- 0 1 0 -->
    <origin xyz="0 0 0.19"/>
    <parent link="chassis"/>
    <child link="imu_link"/>
  </joint>


  <joint type="continuous" name="left_wheel_hinge">
    <origin xyz="0.135 0.135 -0.035" rpy="0 0 0"/>
    <child link="left_wheel"/>
    <parent link="chassis"/>
    <axis xyz="0 1 0" rpy="0 0 0"/>
    <limit effort="100" velocity="100"/>
    <!-- joint_properties damping="0.0" friction="10"/-->
  </joint>

  <joint type="continuous" name="right_wheel_hinge">
    <origin xyz="0.135 -0.135 -0.035" rpy="0 0 0"/>
    <child link="right_wheel"/>
    <parent link="chassis"/>
    <axis xyz="0 1 0" rpy="0 0 0"/>
    <limit effort="100" velocity="100"/>
    <!-- joint_properties damping="0.0" friction="10"/-->
  </joint>

    <joint name="camera_rgb_joint" type="fixed">
      <origin xyz="0.13 0 0.07" rpy="0 0 0"/>
      <parent link="chassis"/>
      <child link="camera_link" />
    </joint>
    <link name="camera_rgb_frame"/>

    <joint name="camera_rgb_optical_joint" type="fixed">
      <origin xyz="0 0 0" rpy="-1.570 0 -1.570" />
      <parent link="camera_rgb_frame" />
      <child link="camera_rgb_optical_frame" />
    </joint>
    <link name="camera_rgb_optical_frame"/>

    <joint name="camera_joint" type="fixed">
      <origin xyz="-0.031 -0.0125 -0.016" rpy="0 0 0"/>
      <child link="camera_rgb_frame"/>
      <parent link="camera_link"/>
    </joint>  
      <link name="camera_link">
      <visual>
       <origin xyz="0 0 0" rpy="0 0 1.570"/>
        <geometry>
         <mesh filename="package://openni_description/mesh/kinect.dae"/>
        </geometry>
      </visual>
  	  <collision>
        <origin xyz="0.0 0.0 0.0" rpy="0 0 0"/>
  	    <geometry>
  	      <box size="0.07271 0.27794 0.073"/>
  	    </geometry>
  	  </collision>
      <inertial>
        <mass value="0.564" />
        <origin xyz="0 0 0" />
        <inertia ixx="0.003881243" ixy="0.0" ixz="0.0"
                 iyy="0.000498940" iyz="0.0"
                 izz="0.003879257" />
      </inertial>
    </link>

    <!-- The fixed joints & links below are usually published by static_transformers launched by the OpenNi launch files. However, for Gazebo simulation we need them, so we add them here.
         (Hence, don't publish them additionally!) -->
	<joint name="camera_depth_joint" type="fixed">
	  <origin xyz="0 0 0" rpy="0 0 0" />
	  <parent link="camera_rgb_frame" />
	  <child link="camera_depth_frame" />
	</joint>
	<link name="camera_depth_frame"/>

	<joint name="camera_depth_optical_joint" type="fixed">
	  <origin xyz="0 0 0" rpy="-1.570 0 -1.570" />
	  <parent link="camera_depth_frame" />
	  <child link="camera_depth_optical_frame" />
	</joint>
	<link name="camera_depth_optical_frame"/>
</robot>
